Workbook

Sheet Output >>

Sheet 1. Income Statement
Q5: FY | AD5: FY | AO5: YTD | AP5: TTM
B6: ($'000s) | E6: 44957 | F6: =EOMONTH(E6,1) -> 44985 | G6: =EOMONTH(F6,1) -> 45016 | H6: =EOMONTH(G6,1) -> 45046 | I6: =EOMONTH(H6,1) -> 45077 | J6: =EOMONTH(I6,1) -> 45107 | K6: =EOMONTH(J6,1) -> 45138 | L6: =EOMONTH(K6,1) -> 45169 | M6: =EOMONTH(L6,1) -> 45199 | ... P6: =EOMONTH(O6,1) -> 45291 | Q6: =YEAR(P6) -> 2023 | R6: =EOMONTH(P6,1) -> 45322 | S6: =EOMONTH(R6,1) -> 45351 | T6: =EOMONTH(S6,1) -> 45382 | U6: =EOMONTH(T6,1) -> 45412 | V6: =EOMONTH(U6,1) -> 45443 | W6: =EOMONTH(V6,1) -> 45473 | X6: =EOMONTH(W6,1) -> 45504 | Y6: =EOMONTH(X6,1) -> 45535 | Z6: =EOMONTH(Y6,1) -> 45565 | ... AC6: =EOMONTH(AB6,1) -> 45657 | AD6: =YEAR(AC6) -> 2024 | AE6: =EOMONTH(AC6,1) -> 45688 | AF6: =EOMONTH(AE6,1) -> 45716 | AG6: =EOMONTH(AF6,1) -> 45747 | AH6: =EOMONTH(AG6,1) -> 45777 | AI6: =EOMONTH(AH6,1) -> 45808 | AJ6: =EOMONTH(AI6,1) -> 45838 | AK6: =EOMONTH(AJ6,1) -> 45869 | AL6: =EOMONTH(AK6,1) -> 45900 | AM6: =EOMONTH(AL6,1) -> 45930 | AN6: =EOMONTH(AM6,1) -> 45961 | AO6: =+AN6 -> 45961 | AP6: =+AO6 -> 45961 | AR6: SUMIF Match
B8: Revenue
B9: =+AR9 -> Fire Sprinkler Installation | E9: =SUMIF('Income Statement Source'!$C:$C,'1. Income Statement'!$AR9,'Income Statement Source'!G:G)/1000 -> 94.66262 | F9: =SUMIF('Income Statement Source'!$C:$C,'1. Income Statement'!$AR9,'Income Statement Source'!H:H)/1000 -> 97.62104 | G9: =SUMIF('Income Statement Source'!$C:$C,'1. Income Statement'!$AR9,'Income Statement Source'!I:I)/1000 -> 109.05163 | H9: =SUMIF('Income Statement Source'!$C:$C,'1. Income Statement'!$AR9,'Income Statement Source'!J:J)/1000 -> 116.69817 | I9: =SUMIF('Income Statement Source'!$C:$C,'1. Income Statement'!$AR9,'Income Statement Source'!K:K)/1000 -> 129.38949 | J9: =SUMIF('Income Statement Source'!$C:$C,'1. Income Statement'!$AR9,'Income Statement Source'!L:L)/1000 -> 139.20879 | K9: =SUMIF('Income Statement Source'!$C:$C,'1. Income Statement'!$AR9,'Income Statement Source'!M:M)/1000 -> 128.77655 | L9: =SUMIF('Income Statement Source'!$C:$C,'1. Income Statement'!$AR9,'Income Statement Source'!N:N)/1000 -> 121.31438 | M9: =SUMIF('Income Statement Source'!$C:$C,'1. Income Statement'!$AR9,'Income Statement Source'!O:O)/1000 -> 132.06497 | N9: =SUMIF('Income Statement Source'!$C:$C,'1. Income Statement'!$AR9,'Income Statement Source'!P:P)/1000 -> 115.39684 | O9: =SUMIF('Income Statement Source'!$C:$C,'1. Income Statement'!$AR9,'Income Statement Source'!Q:Q)/1000 -> 92.35307 | P9: =SUMIF('Income Statement Source'!$C:$C,'1. Income Statement'!$AR9,'Income Statement Source'!R:R)/1000 -> 99.50006 | Q9: =SUM(E9:P9) -> 1376.0376 | R9: =SUMIF('Income Statement Source'!$C:$C,'1. Income Statement'!$AR9,'Income Statement Source'!T:T)/1000 -> 121.5151 | S9: =SUMIF('Income Statement Source'!$C:$C,'1. Income Statement'!$AR9,'Income Statement Source'!U:U)/1000 -> 125.70488 | T9: =SUMIF('Income Statement Source'!$C:$C,'1. Income Statement'!$AR9,'Income Statement Source'!V:V)/1000 -> 139.28441 | U9: =SUMIF('Income Statement Source'!$C:$C,'1. Income Statement'!$AR9,'Income Statement Source'!W:W)/1000 -> 169.39376 | V9: =SUMIF('Income Statement Source'!$C:$C,'1. Income Statement'!$AR9,'Income Statement Source'!X:X)/1000 -> 179.57191 | W9: =SUMIF('Income Statement Source'!$C:$C,'1. Income Statement'!$AR9,'Income Statement Source'!Y:Y)/1000 -> 205.64962 | X9: =SUMIF('Income Statement Source'!$C:$C,'1. Income Statement'!$AR9,'Income Statement Source'!Z:Z)/1000 -> 206.52219 | Y9: =SUMIF('Income Statement Source'!$C:$C,'1. Income Statement'!$AR9,'Income Statement Source'!AA:AA)/1000 -> 204.1675 | Z9: =SUMIF('Income Statement Source'!$C:$C,'1. Income Statement'!$AR9,'Income Statement Source'!AB:AB)/1000 -> 172.58198 | AA9: =SUMIF('Income Statement Source'!$C:$C,'1. Income Statement'!$AR9,'Income Statement Source'!AC:AC)/1000 -> 149.03408 | AB9: =SUMIF('Income Statement Source'!$C:$C,'1. Income Statement'!$AR9,'Income Statement Source'!AD:AD)/1000 -> 150.49911 | AC9: =SUMIF('Income Statement Source'!$C:$C,'1. Income Statement'!$AR9,'Income Statement Source'!AE:AE)/1000 -> 122.23012 | AD9: =SUM(R9:AC9) -> 1946.1547 | AE9: =SUMIF('Income Statement Source'!$C:$C,'1. Income Statement'!$AR9,'Income Statement Source'!AG:AG)/1000 -> 127.52364 | AF9: =SUMIF('Income Statement Source'!$C:$C,'1. Income Statement'!$AR9,'Income Statement Source'!AH:AH)/1000 -> 128.71096 | AG9: =SUMIF('Income Statement Source'!$C:$C,'1. Income Statement'!$AR9,'Income Statement Source'!AI:AI)/1000 -> 154.37443 | AH9: =SUMIF('Income Statement Source'!$C:$C,'1. Income Statement'!$AR9,'Income Statement Source'!AJ:AJ)/1000 -> 180.38214 | AI9: =SUMIF('Income Statement Source'!$C:$C,'1. Income Statement'!$AR9,'Income Statement Source'!AK:AK)/1000 -> 173.05318 | AJ9: =SUMIF('Income Statement Source'!$C:$C,'1. Income Statement'!$AR9,'Income Statement Source'!AL:AL)/1000 -> 206.02639 | AK9: =SUMIF('Income Statement Source'!$C:$C,'1. Income Statement'!$AR9,'Income Statement Source'!AM:AM)/1000 -> 204.11108 | AL9: =SUMIF('Income Statement Source'!$C:$C,'1. Income Statement'!$AR9,'Income Statement Source'!AN:AN)/1000 -> 179.90498 | AM9: =SUMIF('Income Statement Source'!$C:$C,'1. Income Statement'!$AR9,'Income Statement Source'!AO:AO)/1000 -> 193.30511 | AN9: =SUMIF('Income Statement Source'!$C:$C,'1. Income Statement'!$AR9,'Income Statement Source'!AP:AP)/1000 -> 176.64857 | AO9: =SUM(AE9:AN9) -> 1724.0405 | AP9: =SUM(AO9,AB9:AC9) -> 1996.7697 | AR9: Fire Sprinkler Installation
E10: =IFERROR(E9/E$19,0) -> 0.4982872 | F10: =IFERROR(F9/F$19,0) -> 0.42951932 | G10: =IFERROR(G9/G$19,0) -> 0.35450626 | H10: =IFERROR(H9/H$19,0) -> 0.45119255 | I10: =IFERROR(I9/I$19,0) -> 0.47608696 | J10: =IFERROR(J9/J$19,0) -> 0.37802272 | K10: =IFERROR(K9/K$19,0) -> 0.4257124 | L10: =IFERROR(L9/L$19,0) -> 0.4376064 | ... AP10: =IFERROR(AP9/AP$19,0) -> 0.47079517
B11: =+AR11 -> Fire Alarm Installation | E11: =SUMIF('Income Statement Source'!$C:$C,'1. Income Statement'!$AR11,'Income Statement Source'!G:G)/1000 -> 77.60896 | F11: =SUMIF('Income Statement Source'!$C:$C,'1. Income Statement'!$AR11,'Income Statement Source'!H:H)/1000 -> 86.5478 | G11: =SUMIF('Income Statement Source'!$C:$C,'1. Income Statement'!$AR11,'Income Statement Source'!I:I)/1000 -> 84.03452 | H11: =SUMIF('Income Statement Source'!$C:$C,'1. Income Statement'!$AR11,'Income Statement Source'!J:J)/1000 -> 100.14304 | I11: =SUMIF('Income Statement Source'!$C:$C,'1. Income Statement'!$AR11,'Income Statement Source'!K:K)/1000 -> 101.76326 | J11: =SUMIF('Income Statement Source'!$C:$C,'1. Income Statement'!$AR11,'Income Statement Source'!L:L)/1000 -> 116.44295 | K11: =SUMIF('Income Statement Source'!$C:$C,'1. Income Statement'!$AR11,'Income Statement Source'!M:M)/1000 -> 129.76729 | L11: =SUMIF('Income Statement Source'!$C:$C,'1. Income Statement'!$AR11,'Income Statement Source'!N:N)/1000 -> 114.08084 | M11: =SUMIF('Income Statement Source'!$C:$C,'1. Income Statement'!$AR11,'Income Statement Source'!O:O)/1000 -> 107.71489 | N11: =SUMIF('Income Statement Source'!$C:$C,'1. Income Statement'!$AR11,'Income Statement Source'!P:P)/1000 -> 108.33409 | O11: =SUMIF('Income Statement Source'!$C:$C,'1. Income Statement'!$AR11,'Income Statement Source'!Q:Q)/1000 -> 89.03694 | P11: =SUMIF('Income Statement Source'!$C:$C,'1. Income Statement'!$AR11,'Income Statement Source'!R:R)/1000 -> 77.21956 | Q11: =SUM(E11:P11) -> 1192.6941 | R11: =SUMIF('Income Statement Source'!$C:$C,'1. Income Statement'!$AR11,'Income Statement Source'!T:T)/1000 -> 85.34755 | S11: =SUMIF('Income Statement Source'!$C:$C,'1. Income Statement'!$AR11,'Income Statement Source'!U:U)/1000 -> 86.64764 | T11: =SUMIF('Income Statement Source'!$C:$C,'1. Income Statement'!$AR11,'Income Statement Source'!V:V)/1000 -> 94.09094 | U11: =SUMIF('Income Statement Source'!$C:$C,'1. Income Statement'!$AR11,'Income Statement Source'!W:W)/1000 -> 105.72795 | V11: =SUMIF('Income Statement Source'!$C:$C,'1. Income Statement'!$AR11,'Income Statement Source'!X:X)/1000 -> 117.38177 | W11: =SUMIF('Income Statement Source'!$C:$C,'1. Income Statement'!$AR11,'Income Statement Source'!Y:Y)/1000 -> 119.70302 | X11: =SUMIF('Income Statement Source'!$C:$C,'1. Income Statement'!$AR11,'Income Statement Source'!Z:Z)/1000 -> 117.26527 | Y11: =SUMIF('Income Statement Source'!$C:$C,'1. Income Statement'!$AR11,'Income Statement Source'!AA:AA)/1000 -> 130.83706 | Z11: =SUMIF('Income Statement Source'!$C:$C,'1. Income Statement'!$AR11,'Income Statement Source'!AB:AB)/1000 -> 108.45174 | AA11: =SUMIF('Income Statement Source'!$C:$C,'1. Income Statement'!$AR11,'Income Statement Source'!AC:AC)/1000 -> 113.57406 | AB11: =SUMIF('Income Statement Source'!$C:$C,'1. Income Statement'!$AR11,'Income Statement Source'!AD:AD)/1000 -> 98.33674 | AC11: =SUMIF('Income Statement Source'!$C:$C,'1. Income Statement'!$AR11,'Income Statement Source'!AE:AE)/1000 -> 93.0428 | AD11: =SUM(R11:AC11) -> 1270.4065 | AE11: =SUMIF('Income Statement Source'!$C:$C,'1. Income Statement'!$AR11,'Income Statement Source'!AG:AG)/1000 -> 88.38627 | AF11: =SUMIF('Income Statement Source'!$C:$C,'1. Income Statement'!$AR11,'Income Statement Source'!AH:AH)/1000 -> 97.32335 | AG11: =SUMIF('Income Statement Source'!$C:$C,'1. Income Statement'!$AR11,'Income Statement Source'!AI:AI)/1000 -> 95.14147 | AH11: =SUMIF('Income Statement Source'!$C:$C,'1. Income Statement'!$AR11,'Income Statement Source'!AJ:AJ)/1000 -> 113.54869 | AI11: =SUMIF('Income Statement Source'!$C:$C,'1. Income Statement'!$AR11,'Income Statement Source'!AK:AK)/1000 -> 116.15574 | AJ11: =SUMIF('Income Statement Source'!$C:$C,'1. Income Statement'!$AR11,'Income Statement Source'!AL:AL)/1000 -> 132.59605 | AK11: =SUMIF('Income Statement Source'!$C:$C,'1. Income Statement'!$AR11,'Income Statement Source'!AM:AM)/1000 -> 126.67882 | AL11: =SUMIF('Income Statement Source'!$C:$C,'1. Income Statement'!$AR11,'Income Statement Source'!AN:AN)/1000 -> 120.13104 | AM11: =SUMIF('Income Statement Source'!$C:$C,'1. Income Statement'!$AR11,'Income Statement Source'!AO:AO)/1000 -> 116.06038 | AN11: =SUMIF('Income Statement Source'!$C:$C,'1. Income Statement'!$AR11,'Income Statement Source'!AP:AP)/1000 -> 104.1304 | AO11: =SUM(AE11:AN11) -> 1110.1522 | AP11: =SUM(AO11,AB11:AC11) -> 1301.5317 | AR11: Fire Alarm Installation
E12: =IFERROR(E11/E$19,0) -> 0.40851977 | F12: =IFERROR(F11/F$19,0) -> 0.38079857 | G12: =IFERROR(G11/G$19,0) -> 0.27318036 | H12: =IFERROR(H11/H$19,0) -> 0.38718511 | I12: =IFERROR(I11/I$19,0) -> 0.3744366 | J12: =IFERROR(J11/J$19,0) -> 0.31620188 | K12: =IFERROR(K11/K$19,0) -> 0.42898761 | L12: =IFERROR(L11/L$19,0) -> 0.41151351 | ... AP12: =IFERROR(AP11/AP$19,0) -> 0.30687308
B13: =+AR13 -> Inspection & Testing Services | E13: =SUMIF('Income Statement Source'!$C:$C,'1. Income Statement'!$AR13,'Income Statement Source'!G:G)/1000 -> 42.70444 | F13: =SUMIF('Income Statement Source'!$C:$C,'1. Income Statement'!$AR13,'Income Statement Source'!H:H)/1000 -> 43.1109 | G13: =SUMIF('Income Statement Source'!$C:$C,'1. Income Statement'!$AR13,'Income Statement Source'!I:I)/1000 -> 43.65919 | H13: =SUMIF('Income Statement Source'!$C:$C,'1. Income Statement'!$AR13,'Income Statement Source'!J:J)/1000 -> 41.80262 | I13: =SUMIF('Income Statement Source'!$C:$C,'1. Income Statement'!$AR13,'Income Statement Source'!K:K)/1000 -> 40.62426 | J13: =SUMIF('Income Statement Source'!$C:$C,'1. Income Statement'!$AR13,'Income Statement Source'!L:L)/1000 -> 44.83388 | K13: =SUMIF('Income Statement Source'!$C:$C,'1. Income Statement'!$AR13,'Income Statement Source'!M:M)/1000 -> 43.95275 | L13: =SUMIF('Income Statement Source'!$C:$C,'1. Income Statement'!$AR13,'Income Statement Source'!N:N)/1000 -> 41.82737 | M13: =SUMIF('Income Statement Source'!$C:$C,'1. Income Statement'!$AR13,'Income Statement Source'!O:O)/1000 -> 43.05176 | N13: =SUMIF('Income Statement Source'!$C:$C,'1. Income Statement'!$AR13,'Income Statement Source'!P:P)/1000 -> 43.42413 | O13: =SUMIF('Income Statement Source'!$C:$C,'1. Income Statement'!$AR13,'Income Statement Source'!Q:Q)/1000 -> 43.90217 | P13: =SUMIF('Income Statement Source'!$C:$C,'1. Income Statement'!$AR13,'Income Statement Source'!R:R)/1000 -> 43.46634 | Q13: =SUM(E13:P13) -> 516.35981 | R13: =SUMIF('Income Statement Source'!$C:$C,'1. Income Statement'!$AR13,'Income Statement Source'!T:T)/1000 -> 44.16799 | S13: =SUMIF('Income Statement Source'!$C:$C,'1. Income Statement'!$AR13,'Income Statement Source'!U:U)/1000 -> 45.85822 | T13: =SUMIF('Income Statement Source'!$C:$C,'1. Income Statement'!$AR13,'Income Statement Source'!V:V)/1000 -> 47.05096 | U13: =SUMIF('Income Statement Source'!$C:$C,'1. Income Statement'!$AR13,'Income Statement Source'!W:W)/1000 -> 44.57798 | V13: =SUMIF('Income Statement Source'!$C:$C,'1. Income Statement'!$AR13,'Income Statement Source'!X:X)/1000 -> 43.08885 | W13: =SUMIF('Income Statement Source'!$C:$C,'1. Income Statement'!$AR13,'Income Statement Source'!Y:Y)/1000 -> 43.93139 | X13: =SUMIF('Income Statement Source'!$C:$C,'1. Income Statement'!$AR13,'Income Statement Source'!Z:Z)/1000 -> 47.31837 | Y13: =SUMIF('Income Statement Source'!$C:$C,'1. Income Statement'!$AR13,'Income Statement Source'!AA:AA)/1000 -> 46.08266 | Z13: =SUMIF('Income Statement Source'!$C:$C,'1. Income Statement'!$AR13,'Income Statement Source'!AB:AB)/1000 -> 43.8666 | AA13: =SUMIF('Income Statement Source'!$C:$C,'1. Income Statement'!$AR13,'Income Statement Source'!AC:AC)/1000 -> 42.68755 | AB13: =SUMIF('Income Statement Source'!$C:$C,'1. Income Statement'!$AR13,'Income Statement Source'!AD:AD)/1000 -> 43.86092 | AC13: =SUMIF('Income Statement Source'!$C:$C,'1. Income Statement'!$AR13,'Income Statement Source'!AE:AE)/1000 -> 46.83949 | AD13: =SUM(R13:AC13) -> 539.33098 | AE13: =SUMIF('Income Statement Source'!$C:$C,'1. Income Statement'!$AR13,'Income Statement Source'!AG:AG)/1000 -> 49.42844 | AF13: =SUMIF('Income Statement Source'!$C:$C,'1. Income Statement'!$AR13,'Income Statement Source'!AH:AH)/1000 -> 47.0902 | AG13: =SUMIF('Income Statement Source'!$C:$C,'1. Income Statement'!$AR13,'Income Statement Source'!AI:AI)/1000 -> 46.45931 | AH13: =SUMIF('Income Statement Source'!$C:$C,'1. Income Statement'!$AR13,'Income Statement Source'!AJ:AJ)/1000 -> 46.91218 | AI13: =SUMIF('Income Statement Source'!$C:$C,'1. Income Statement'!$AR13,'Income Statement Source'!AK:AK)/1000 -> 48.69308 | AJ13: =SUMIF('Income Statement Source'!$C:$C,'1. Income Statement'!$AR13,'Income Statement Source'!AL:AL)/1000 -> 47.85082 | AK13: =SUMIF('Income Statement Source'!$C:$C,'1. Income Statement'!$AR13,'Income Statement Source'!AM:AM)/1000 -> 45.19238 | AL13: =SUMIF('Income Statement Source'!$C:$C,'1. Income Statement'!$AR13,'Income Statement Source'!AN:AN)/1000 -> 47.09875 | AM13: =SUMIF('Income Statement Source'!$C:$C,'1. Income Statement'!$AR13,'Income Statement Source'!AO:AO)/1000 -> 47.70437 | AN13: =SUMIF('Income Statement Source'!$C:$C,'1. Income Statement'!$AR13,'Income Statement Source'!AP:AP)/1000 -> 48.08421 | AO13: =SUM(AE13:AN13) -> 474.51374 | AP13: =SUM(AO13,AB13:AC13) -> 565.21415 | AR13: Inspection & Testing Services
E14: =IFERROR(E13/E$19,0) -> 0.22478858 | F14: =IFERROR(F13/F$19,0) -> 0.18968211 | G14: =IFERROR(G13/G$19,0) -> 0.14192778 | H14: =IFERROR(H13/H$19,0) -> 0.16162234 | I14: =IFERROR(I13/I$19,0) -> 0.14947644 | J14: =IFERROR(J13/J$19,0) -> 0.1217468 | K14: =IFERROR(K13/K$19,0) -> 0.14529999 | L14: =IFERROR(L13/L$19,0) -> 0.15088009 | ... AP14: =IFERROR(AP13/AP$19,0) -> 0.13326529
B15: =+AR15 -> Maintenance Contracts | E15: =SUMIF('Income Statement Source'!$C:$C,'1. Income Statement'!$AR15,'Income Statement Source'!G:G)/1000 -> 0 | F15: =SUMIF('Income Statement Source'!$C:$C,'1. Income Statement'!$AR15,'Income Statement Source'!H:H)/1000 -> 0 | G15: =SUMIF('Income Statement Source'!$C:$C,'1. Income Statement'!$AR15,'Income Statement Source'!I:I)/1000 -> 70.87019 | H15: =SUMIF('Income Statement Source'!$C:$C,'1. Income Statement'!$AR15,'Income Statement Source'!J:J)/1000 -> 0 | I15: =SUMIF('Income Statement Source'!$C:$C,'1. Income Statement'!$AR15,'Income Statement Source'!K:K)/1000 -> 0 | J15: =SUMIF('Income Statement Source'!$C:$C,'1. Income Statement'!$AR15,'Income Statement Source'!L:L)/1000 -> 67.76947 | K15: =SUMIF('Income Statement Source'!$C:$C,'1. Income Statement'!$AR15,'Income Statement Source'!M:M)/1000 -> 0 | L15: =SUMIF('Income Statement Source'!$C:$C,'1. Income Statement'!$AR15,'Income Statement Source'!N:N)/1000 -> 0 | M15: =SUMIF('Income Statement Source'!$C:$C,'1. Income Statement'!$AR15,'Income Statement Source'!O:O)/1000 -> 71.44845 | N15: =SUMIF('Income Statement Source'!$C:$C,'1. Income Statement'!$AR15,'Income Statement Source'!P:P)/1000 -> 0 | O15: =SUMIF('Income Statement Source'!$C:$C,'1. Income Statement'!$AR15,'Income Statement Source'!Q:Q)/1000 -> 0 | P15: =SUMIF('Income Statement Source'!$C:$C,'1. Income Statement'!$AR15,'Income Statement Source'!R:R)/1000 -> 70.38265 | Q15: =SUM(E15:P15) -> 280.47076 | R15: =SUMIF('Income Statement Source'!$C:$C,'1. Income Statement'!$AR15,'Income Statement Source'!T:T)/1000 -> 0 | S15: =SUMIF('Income Statement Source'!$C:$C,'1. Income Statement'!$AR15,'Income Statement Source'!U:U)/1000 -> 0 | T15: =SUMIF('Income Statement Source'!$C:$C,'1. Income Statement'!$AR15,'Income Statement Source'!V:V)/1000 -> 72.44887 | U15: =SUMIF('Income Statement Source'!$C:$C,'1. Income Statement'!$AR15,'Income Statement Source'!W:W)/1000 -> 0 | V15: =SUMIF('Income Statement Source'!$C:$C,'1. Income Statement'!$AR15,'Income Statement Source'!X:X)/1000 -> 0 | W15: =SUMIF('Income Statement Source'!$C:$C,'1. Income Statement'!$AR15,'Income Statement Source'!Y:Y)/1000 -> 68.36416 | X15: =SUMIF('Income Statement Source'!$C:$C,'1. Income Statement'!$AR15,'Income Statement Source'!Z:Z)/1000 -> 0 | Y15: =SUMIF('Income Statement Source'!$C:$C,'1. Income Statement'!$AR15,'Income Statement Source'!AA:AA)/1000 -> 0 | Z15: =SUMIF('Income Statement Source'!$C:$C,'1. Income Statement'!$AR15,'Income Statement Source'!AB:AB)/1000 -> 73.20211 | AA15: =SUMIF('Income Statement Source'!$C:$C,'1. Income Statement'!$AR15,'Income Statement Source'!AC:AC)/1000 -> 0 | AB15: =SUMIF('Income Statement Source'!$C:$C,'1. Income Statement'!$AR15,'Income Statement Source'!AD:AD)/1000 -> 0 | AC15: =SUMIF('Income Statement Source'!$C:$C,'1. Income Statement'!$AR15,'Income Statement Source'!AE:AE)/1000 -> 75.40684 | AD15: =SUM(R15:AC15) -> 289.42198 | AE15: =SUMIF('Income Statement Source'!$C:$C,'1. Income Statement'!$AR15,'Income Statement Source'!AG:AG)/1000 -> 0 | AF15: =SUMIF('Income Statement Source'!$C:$C,'1. Income Statement'!$AR15,'Income Statement Source'!AH:AH)/1000 -> 0 | AG15: =SUMIF('Income Statement Source'!$C:$C,'1. Income Statement'!$AR15,'Income Statement Source'!AI:AI)/1000 -> 76.3279 | AH15: =SUMIF('Income Statement Source'!$C:$C,'1. Income Statement'!$AR15,'Income Statement Source'!AJ:AJ)/1000 -> 0 | AI15: =SUMIF('Income Statement Source'!$C:$C,'1. Income Statement'!$AR15,'Income Statement Source'!AK:AK)/1000 -> 0 | AJ15: =SUMIF('Income Statement Source'!$C:$C,'1. Income Statement'!$AR15,'Income Statement Source'!AL:AL)/1000 -> 78.2589 | AK15: =SUMIF('Income Statement Source'!$C:$C,'1. Income Statement'!$AR15,'Income Statement Source'!AM:AM)/1000 -> 0 | AL15: =SUMIF('Income Statement Source'!$C:$C,'1. Income Statement'!$AR15,'Income Statement Source'!AN:AN)/1000 -> 0 | AM15: =SUMIF('Income Statement Source'!$C:$C,'1. Income Statement'!$AR15,'Income Statement Source'!AO:AO)/1000 -> 72.9321 | AN15: =SUMIF('Income Statement Source'!$C:$C,'1. Income Statement'!$AR15,'Income Statement Source'!AP:AP)/1000 -> 0 | AO15: =SUM(AE15:AN15) -> 227.5189 | AP15: =SUM(AO15,AB15:AC15) -> 302.92574 | AR15: Maintenance Contracts
E16: =IFERROR(E15/E$19,0) -> 0 | F16: =IFERROR(F15/F$19,0) -> 0 | G16: =IFERROR(G15/G$19,0) -> 0.23038561 | H16: =IFERROR(H15/H$19,0) -> 0 | I16: =IFERROR(I15/I$19,0) -> 0 | J16: =IFERROR(J15/J$19,0) -> 0.1840286 | K16: =IFERROR(K15/K$19,0) -> 0 | L16: =IFERROR(L15/L$19,0) -> 0 | ... AP16: =IFERROR(AP15/AP$19,0) -> 0.071423347
B17: =+AR17 -> WIP Adjustment | E17: =SUMIF('Income Statement Source'!$C:$C,'1. Income Statement'!$AR17,'Income Statement Source'!G:G)/1000 -> -25 | F17: =SUMIF('Income Statement Source'!$C:$C,'1. Income Statement'!$AR17,'Income Statement Source'!H:H)/1000 -> 0 | G17: =SUMIF('Income Statement Source'!$C:$C,'1. Income Statement'!$AR17,'Income Statement Source'!I:I)/1000 -> 0 | H17: =SUMIF('Income Statement Source'!$C:$C,'1. Income Statement'!$AR17,'Income Statement Source'!J:J)/1000 -> 0 | I17: =SUMIF('Income Statement Source'!$C:$C,'1. Income Statement'!$AR17,'Income Statement Source'!K:K)/1000 -> 0 | J17: =SUMIF('Income Statement Source'!$C:$C,'1. Income Statement'!$AR17,'Income Statement Source'!L:L)/1000 -> 0 | K17: =SUMIF('Income Statement Source'!$C:$C,'1. Income Statement'!$AR17,'Income Statement Source'!M:M)/1000 -> 0 | L17: =SUMIF('Income Statement Source'!$C:$C,'1. Income Statement'!$AR17,'Income Statement Source'!N:N)/1000 -> 0 | M17: =SUMIF('Income Statement Source'!$C:$C,'1. Income Statement'!$AR17,'Income Statement Source'!O:O)/1000 -> 0 | N17: =SUMIF('Income Statement Source'!$C:$C,'1. Income Statement'!$AR17,'Income Statement Source'!P:P)/1000 -> 0 | O17: =SUMIF('Income Statement Source'!$C:$C,'1. Income Statement'!$AR17,'Income Statement Source'!Q:Q)/1000 -> 0 | P17: =SUMIF('Income Statement Source'!$C:$C,'1. Income Statement'!$AR17,'Income Statement Source'!R:R)/1000 -> 48.52345 | Q17: =SUM(E17:P17) -> 23.52345 | R17: =SUMIF('Income Statement Source'!$C:$C,'1. Income Statement'!$AR17,'Income Statement Source'!T:T)/1000 -> -48.52345 | S17: =SUMIF('Income Statement Source'!$C:$C,'1. Income Statement'!$AR17,'Income Statement Source'!U:U)/1000 -> 0 | T17: =SUMIF('Income Statement Source'!$C:$C,'1. Income Statement'!$AR17,'Income Statement Source'!V:V)/1000 -> 0 | U17: =SUMIF('Income Statement Source'!$C:$C,'1. Income Statement'!$AR17,'Income Statement Source'!W:W)/1000 -> 0 | V17: =SUMIF('Income Statement Source'!$C:$C,'1. Income Statement'!$AR17,'Income Statement Source'!X:X)/1000 -> 0 | W17: =SUMIF('Income Statement Source'!$C:$C,'1. Income Statement'!$AR17,'Income Statement Source'!Y:Y)/1000 -> 0 | X17: =SUMIF('Income Statement Source'!$C:$C,'1. Income Statement'!$AR17,'Income Statement Source'!Z:Z)/1000 -> 0 | Y17: =SUMIF('Income Statement Source'!$C:$C,'1. Income Statement'!$AR17,'Income Statement Source'!AA:AA)/1000 -> 0 | Z17: =SUMIF('Income Statement Source'!$C:$C,'1. Income Statement'!$AR17,'Income Statement Source'!AB:AB)/1000 -> 0 | AA17: =SUMIF('Income Statement Source'!$C:$C,'1. Income Statement'!$AR17,'Income Statement Source'!AC:AC)/1000 -> 0 | AB17: =SUMIF('Income Statement Source'!$C:$C,'1. Income Statement'!$AR17,'Income Statement Source'!AD:AD)/1000 -> 0 | AC17: =SUMIF('Income Statement Source'!$C:$C,'1. Income Statement'!$AR17,'Income Statement Source'!AE:AE)/1000 -> 52.89123 | AD17: =SUM(R17:AC17) -> 4.36778 | AE17: =SUMIF('Income Statement Source'!$C:$C,'1. Income Statement'!$AR17,'Income Statement Source'!AG:AG)/1000 -> -52.89123 | AF17: =SUMIF('Income Statement Source'!$C:$C,'1. Income Statement'!$AR17,'Income Statement Source'!AH:AH)/1000 -> 9.4342 | AG17: =SUMIF('Income Statement Source'!$C:$C,'1. Income Statement'!$AR17,'Income Statement Source'!AI:AI)/1000 -> 9.34611 | AH17: =SUMIF('Income Statement Source'!$C:$C,'1. Income Statement'!$AR17,'Income Statement Source'!AJ:AJ)/1000 -> 8.09037 | AI17: =SUMIF('Income Statement Source'!$C:$C,'1. Income Statement'!$AR17,'Income Statement Source'!AK:AK)/1000 -> 7.8028 | AJ17: =SUMIF('Income Statement Source'!$C:$C,'1. Income Statement'!$AR17,'Income Statement Source'!AL:AL)/1000 -> 7.65396 | AK17: =SUMIF('Income Statement Source'!$C:$C,'1. Income Statement'!$AR17,'Income Statement Source'!AM:AM)/1000 -> 9.07126 | AL17: =SUMIF('Income Statement Source'!$C:$C,'1. Income Statement'!$AR17,'Income Statement Source'!AN:AN)/1000 -> 6.80614 | AM17: =SUMIF('Income Statement Source'!$C:$C,'1. Income Statement'!$AR17,'Income Statement Source'!AO:AO)/1000 -> 7.23004 | AN17: =SUMIF('Income Statement Source'!$C:$C,'1. Income Statement'!$AR17,'Income Statement Source'!AP:AP)/1000 -> 9.39436 | AO17: =SUM(AE17:AN17) -> 21.93801 | AP17: =SUM(AO17,AB17:AC17) -> 74.82924 | AR17: WIP Adjustment
E18: =IFERROR(E17/E$19,0) -> -0.13159556 | F18: =IFERROR(F17/F$19,0) -> 0 | G18: =IFERROR(G17/G$19,0) -> 0 | H18: =IFERROR(H17/H$19,0) -> 0 | I18: =IFERROR(I17/I$19,0) -> 0 | J18: =IFERROR(J17/J$19,0) -> 0 | K18: =IFERROR(K17/K$19,0) -> 0 | L18: =IFERROR(L17/L$19,0) -> 0 | ... AP18: =IFERROR(AP17/AP$19,0) -> 0.017643119
B19: =+B8 -> Revenue | E19: =SUM(E9,E11,E13,E15,E17) -> 189.97602 | F19: =SUM(F9,F11,F13,F15,F17) -> 227.27974 | G19: =SUM(G9,G11,G13,G15,G17) -> 307.61553 | H19: =SUM(H9,H11,H13,H15,H17) -> 258.64383 | I19: =SUM(I9,I11,I13,I15,I17) -> 271.77701 | J19: =SUM(J9,J11,J13,J15,J17) -> 368.25509 | K19: =SUM(K9,K11,K13,K15,K17) -> 302.49659 | L19: =SUM(L9,L11,L13,L15,L17) -> 277.22259 | ... AP19: =SUM(AP9,AP11,AP13,AP15,AP17) -> 4241.2706
B22: Cost of Goods Sold
B23: Materials & Equipment
B24: =+AR24 -> Sprinkler Materials & Fittings | E24: =SUMIF('Income Statement Source'!$C:$C,'1. Income Statement'!$AR24,'Income Statement Source'!G:G)/1000 -> 18.7739 | F24: =SUMIF('Income Statement Source'!$C:$C,'1. Income Statement'!$AR24,'Income Statement Source'!H:H)/1000 -> 22.36071 | G24: =SUMIF('Income Statement Source'!$C:$C,'1. Income Statement'!$AR24,'Income Statement Source'!I:I)/1000 -> 30.52923 | H24: =SUMIF('Income Statement Source'!$C:$C,'1. Income Statement'!$AR24,'Income Statement Source'!J:J)/1000 -> 26.31319 | I24: =SUMIF('Income Statement Source'!$C:$C,'1. Income Statement'!$AR24,'Income Statement Source'!K:K)/1000 -> 25.1539 | J24: =SUMIF('Income Statement Source'!$C:$C,'1. Income Statement'!$AR24,'Income Statement Source'!L:L)/1000 -> 35.27347 | K24: =SUMIF('Income Statement Source'!$C:$C,'1. Income Statement'!$AR24,'Income Statement Source'!M:M)/1000 -> 32.34572 | L24: =SUMIF('Income Statement Source'!$C:$C,'1. Income Statement'!$AR24,'Income Statement Source'!N:N)/1000 -> 27.19652 | M24: =SUMIF('Income Statement Source'!$C:$C,'1. Income Statement'!$AR24,'Income Statement Source'!O:O)/1000 -> 34.61393 | N24: =SUMIF('Income Statement Source'!$C:$C,'1. Income Statement'!$AR24,'Income Statement Source'!P:P)/1000 -> 26.91335 | O24: =SUMIF('Income Statement Source'!$C:$C,'1. Income Statement'!$AR24,'Income Statement Source'!Q:Q)/1000 -> 22.13631 | P24: =SUMIF('Income Statement Source'!$C:$C,'1. Income Statement'!$AR24,'Income Statement Source'!R:R)/1000 -> 34.79761 | Q24: =SUM(E24:P24) -> 336.40784 | R24: =SUMIF('Income Statement Source'!$C:$C,'1. Income Statement'!$AR24,'Income Statement Source'!T:T)/1000 -> 28.66928 | S24: =SUMIF('Income Statement Source'!$C:$C,'1. Income Statement'!$AR24,'Income Statement Source'!U:U)/1000 -> 36.19647 | T24: =SUMIF('Income Statement Source'!$C:$C,'1. Income Statement'!$AR24,'Income Statement Source'!V:V)/1000 -> 51.79314 | U24: =SUMIF('Income Statement Source'!$C:$C,'1. Income Statement'!$AR24,'Income Statement Source'!W:W)/1000 -> 42.45691 | V24: =SUMIF('Income Statement Source'!$C:$C,'1. Income Statement'!$AR24,'Income Statement Source'!X:X)/1000 -> 49.58224 | W24: =SUMIF('Income Statement Source'!$C:$C,'1. Income Statement'!$AR24,'Income Statement Source'!Y:Y)/1000 -> 54.22888 | X24: =SUMIF('Income Statement Source'!$C:$C,'1. Income Statement'!$AR24,'Income Statement Source'!Z:Z)/1000 -> 47.7458 | Y24: =SUMIF('Income Statement Source'!$C:$C,'1. Income Statement'!$AR24,'Income Statement Source'!AA:AA)/1000 -> 56.03896 | Z24: =SUMIF('Income Statement Source'!$C:$C,'1. Income Statement'!$AR24,'Income Statement Source'!AB:AB)/1000 -> 52.2476 | AA24: =SUMIF('Income Statement Source'!$C:$C,'1. Income Statement'!$AR24,'Income Statement Source'!AC:AC)/1000 -> 44.13816 | AB24: =SUMIF('Income Statement Source'!$C:$C,'1. Income Statement'!$AR24,'Income Statement Source'!AD:AD)/1000 -> 37.54888 | AC24: =SUMIF('Income Statement Source'!$C:$C,'1. Income Statement'!$AR24,'Income Statement Source'!AE:AE)/1000 -> 53.87737 | AD24: =SUM(R24:AC24) -> 554.52369 | AE24: =SUMIF('Income Statement Source'!$C:$C,'1. Income Statement'!$AR24,'Income Statement Source'!AG:AG)/1000 -> 22.32297 | AF24: =SUMIF('Income Statement Source'!$C:$C,'1. Income Statement'!$AR24,'Income Statement Source'!AH:AH)/1000 -> 26.3794 | AG24: =SUMIF('Income Statement Source'!$C:$C,'1. Income Statement'!$AR24,'Income Statement Source'!AI:AI)/1000 -> 39.4709 | AH24: =SUMIF('Income Statement Source'!$C:$C,'1. Income Statement'!$AR24,'Income Statement Source'!AJ:AJ)/1000 -> 33.33789 | AI24: =SUMIF('Income Statement Source'!$C:$C,'1. Income Statement'!$AR24,'Income Statement Source'!AK:AK)/1000 -> 32.72787 | AJ24: =SUMIF('Income Statement Source'!$C:$C,'1. Income Statement'!$AR24,'Income Statement Source'!AL:AL)/1000 -> 43.80515 | AK24: =SUMIF('Income Statement Source'!$C:$C,'1. Income Statement'!$AR24,'Income Statement Source'!AM:AM)/1000 -> 38.10798 | AL24: =SUMIF('Income Statement Source'!$C:$C,'1. Income Statement'!$AR24,'Income Statement Source'!AN:AN)/1000 -> 37.87525 | AM24: =SUMIF('Income Statement Source'!$C:$C,'1. Income Statement'!$AR24,'Income Statement Source'!AO:AO)/1000 -> 46.60732 | AN24: =SUMIF('Income Statement Source'!$C:$C,'1. Income Statement'!$AR24,'Income Statement Source'!AP:AP)/1000 -> 35.48698 | AO24: =SUM(AE24:AN24) -> 356.12171 | AP24: =SUM(AO24,AB24:AC24) -> 447.54796 | AR24: Sprinkler Materials & Fittings
B25: =+AR25 -> Alarm Equipment & Devices | E25: =SUMIF('Income Statement Source'!$C:$C,'1. Income Statement'!$AR25,'Income Statement Source'!G:G)/1000 -> 14.5666 | F25: =SUMIF('Income Statement Source'!$C:$C,'1. Income Statement'!$AR25,'Income Statement Source'!H:H)/1000 -> 19.50343 | G25: =SUMIF('Income Statement Source'!$C:$C,'1. Income Statement'!$AR25,'Income Statement Source'!I:I)/1000 -> 26.00369 | H25: =SUMIF('Income Statement Source'!$C:$C,'1. Income Statement'!$AR25,'Income Statement Source'!J:J)/1000 -> 20.26115 | I25: =SUMIF('Income Statement Source'!$C:$C,'1. Income Statement'!$AR25,'Income Statement Source'!K:K)/1000 -> 22.37212 | J25: =SUMIF('Income Statement Source'!$C:$C,'1. Income Statement'!$AR25,'Income Statement Source'!L:L)/1000 -> 28.26905 | K25: =SUMIF('Income Statement Source'!$C:$C,'1. Income Statement'!$AR25,'Income Statement Source'!M:M)/1000 -> 24.85563 | L25: =SUMIF('Income Statement Source'!$C:$C,'1. Income Statement'!$AR25,'Income Statement Source'!N:N)/1000 -> 20.78975 | M25: =SUMIF('Income Statement Source'!$C:$C,'1. Income Statement'!$AR25,'Income Statement Source'!O:O)/1000 -> 29.16329 | N25: =SUMIF('Income Statement Source'!$C:$C,'1. Income Statement'!$AR25,'Income Statement Source'!P:P)/1000 -> 21.53118 | O25: =SUMIF('Income Statement Source'!$C:$C,'1. Income Statement'!$AR25,'Income Statement Source'!Q:Q)/1000 -> 17.53121 | P25: =SUMIF('Income Statement Source'!$C:$C,'1. Income Statement'!$AR25,'Income Statement Source'!R:R)/1000 -> 24.99498 | Q25: =SUM(E25:P25) -> 269.84208 | R25: =SUMIF('Income Statement Source'!$C:$C,'1. Income Statement'!$AR25,'Income Statement Source'!T:T)/1000 -> 14.94188 | S25: =SUMIF('Income Statement Source'!$C:$C,'1. Income Statement'!$AR25,'Income Statement Source'!U:U)/1000 -> 20.16927 | T25: =SUMIF('Income Statement Source'!$C:$C,'1. Income Statement'!$AR25,'Income Statement Source'!V:V)/1000 -> 26.32557 | U25: =SUMIF('Income Statement Source'!$C:$C,'1. Income Statement'!$AR25,'Income Statement Source'!W:W)/1000 -> 25.80505 | V25: =SUMIF('Income Statement Source'!$C:$C,'1. Income Statement'!$AR25,'Income Statement Source'!X:X)/1000 -> 27.24572 | W25: =SUMIF('Income Statement Source'!$C:$C,'1. Income Statement'!$AR25,'Income Statement Source'!Y:Y)/1000 -> 32.45994 | X25: =SUMIF('Income Statement Source'!$C:$C,'1. Income Statement'!$AR25,'Income Statement Source'!Z:Z)/1000 -> 27.85306 | Y25: =SUMIF('Income Statement Source'!$C:$C,'1. Income Statement'!$AR25,'Income Statement Source'!AA:AA)/1000 -> 28.9749 | Z25: =SUMIF('Income Statement Source'!$C:$C,'1. Income Statement'!$AR25,'Income Statement Source'!AB:AB)/1000 -> 30.56051 | AA25: =SUMIF('Income Statement Source'!$C:$C,'1. Income Statement'!$AR25,'Income Statement Source'!AC:AC)/1000 -> 25.49331 | AB25: =SUMIF('Income Statement Source'!$C:$C,'1. Income Statement'!$AR25,'Income Statement Source'!AD:AD)/1000 -> 21.9899 | AC25: =SUMIF('Income Statement Source'!$C:$C,'1. Income Statement'!$AR25,'Income Statement Source'!AE:AE)/1000 -> 31.29619 | AD25: =SUM(R25:AC25) -> 313.1153 | AE25: =SUMIF('Income Statement Source'!$C:$C,'1. Income Statement'!$AR25,'Income Statement Source'!AG:AG)/1000 -> 15.63756 | AF25: =SUMIF('Income Statement Source'!$C:$C,'1. Income Statement'!$AR25,'Income Statement Source'!AH:AH)/1000 -> 23.6607 | AG25: =SUMIF('Income Statement Source'!$C:$C,'1. Income Statement'!$AR25,'Income Statement Source'!AI:AI)/1000 -> 31.61507 | AH25: =SUMIF('Income Statement Source'!$C:$C,'1. Income Statement'!$AR25,'Income Statement Source'!AJ:AJ)/1000 -> 28.20431 | AI25: =SUMIF('Income Statement Source'!$C:$C,'1. Income Statement'!$AR25,'Income Statement Source'!AK:AK)/1000 -> 27.13521 | AJ25: =SUMIF('Income Statement Source'!$C:$C,'1. Income Statement'!$AR25,'Income Statement Source'!AL:AL)/1000 -> 39.05671 | AK25: =SUMIF('Income Statement Source'!$C:$C,'1. Income Statement'!$AR25,'Income Statement Source'!AM:AM)/1000 -> 30.74309 | AL25: =SUMIF('Income Statement Source'!$C:$C,'1. Income Statement'!$AR25,'Income Statement Source'!AN:AN)/1000 -> 28.31626 | AM25: =SUMIF('Income Statement Source'!$C:$C,'1. Income Statement'!$AR25,'Income Statement Source'!AO:AO)/1000 -> 37.5884 | AN25: =SUMIF('Income Statement Source'!$C:$C,'1. Income Statement'!$AR25,'Income Statement Source'!AP:AP)/1000 -> 25.3577 | AO25: =SUM(AE25:AN25) -> 287.31501 | AP25: =SUM(AO25,AB25:AC25) -> 340.6011 | AR25: Alarm Equipment & Devices
B26: =+AR26 -> Pipe & Valves | E26: =SUMIF('Income Statement Source'!$C:$C,'1. Income Statement'!$AR26,'Income Statement Source'!G:G)/1000 -> 7.96719 | F26: =SUMIF('Income Statement Source'!$C:$C,'1. Income Statement'!$AR26,'Income Statement Source'!H:H)/1000 -> 8.80689 | G26: =SUMIF('Income Statement Source'!$C:$C,'1. Income Statement'!$AR26,'Income Statement Source'!I:I)/1000 -> 12.74384 | H26: =SUMIF('Income Statement Source'!$C:$C,'1. Income Statement'!$AR26,'Income Statement Source'!J:J)/1000 -> 9.67119 | I26: =SUMIF('Income Statement Source'!$C:$C,'1. Income Statement'!$AR26,'Income Statement Source'!K:K)/1000 -> 11.5685 | J26: =SUMIF('Income Statement Source'!$C:$C,'1. Income Statement'!$AR26,'Income Statement Source'!L:L)/1000 -> 15.43408 | K26: =SUMIF('Income Statement Source'!$C:$C,'1. Income Statement'!$AR26,'Income Statement Source'!M:M)/1000 -> 12.15675 | L26: =SUMIF('Income Statement Source'!$C:$C,'1. Income Statement'!$AR26,'Income Statement Source'!N:N)/1000 -> 10.3325 | M26: =SUMIF('Income Statement Source'!$C:$C,'1. Income Statement'!$AR26,'Income Statement Source'!O:O)/1000 -> 14.53934 | N26: =SUMIF('Income Statement Source'!$C:$C,'1. Income Statement'!$AR26,'Income Statement Source'!P:P)/1000 -> 11.06018 | O26: =SUMIF('Income Statement Source'!$C:$C,'1. Income Statement'!$AR26,'Income Statement Source'!Q:Q)/1000 -> 9.26131 | P26: =SUMIF('Income Statement Source'!$C:$C,'1. Income Statement'!$AR26,'Income Statement Source'!R:R)/1000 -> 14.45518 | Q26: =SUM(E26:P26) -> 137.99695 | R26: =SUMIF('Income Statement Source'!$C:$C,'1. Income Statement'!$AR26,'Income Statement Source'!T:T)/1000 -> 10.53007 | S26: =SUMIF('Income Statement Source'!$C:$C,'1. Income Statement'!$AR26,'Income Statement Source'!U:U)/1000 -> 14.37085 | T26: =SUMIF('Income Statement Source'!$C:$C,'1. Income Statement'!$AR26,'Income Statement Source'!V:V)/1000 -> 19.52075 | U26: =SUMIF('Income Statement Source'!$C:$C,'1. Income Statement'!$AR26,'Income Statement Source'!W:W)/1000 -> 18.57891 | V26: =SUMIF('Income Statement Source'!$C:$C,'1. Income Statement'!$AR26,'Income Statement Source'!X:X)/1000 -> 19.3347 | W26: =SUMIF('Income Statement Source'!$C:$C,'1. Income Statement'!$AR26,'Income Statement Source'!Y:Y)/1000 -> 24.45855 | X26: =SUMIF('Income Statement Source'!$C:$C,'1. Income Statement'!$AR26,'Income Statement Source'!Z:Z)/1000 -> 18.69852 | Y26: =SUMIF('Income Statement Source'!$C:$C,'1. Income Statement'!$AR26,'Income Statement Source'!AA:AA)/1000 -> 19.93018 | Z26: =SUMIF('Income Statement Source'!$C:$C,'1. Income Statement'!$AR26,'Income Statement Source'!AB:AB)/1000 -> 23.22331 | AA26: =SUMIF('Income Statement Source'!$C:$C,'1. Income Statement'!$AR26,'Income Statement Source'!AC:AC)/1000 -> 16.76829 | AB26: =SUMIF('Income Statement Source'!$C:$C,'1. Income Statement'!$AR26,'Income Statement Source'!AD:AD)/1000 -> 14.90274 | AC26: =SUMIF('Income Statement Source'!$C:$C,'1. Income Statement'!$AR26,'Income Statement Source'!AE:AE)/1000 -> 22.12784 | AD26: =SUM(R26:AC26) -> 222.44471 | AE26: =SUMIF('Income Statement Source'!$C:$C,'1. Income Statement'!$AR26,'Income Statement Source'!AG:AG)/1000 -> 8.4189 | AF26: =SUMIF('Income Statement Source'!$C:$C,'1. Income Statement'!$AR26,'Income Statement Source'!AH:AH)/1000 -> 12.34643 | AG26: =SUMIF('Income Statement Source'!$C:$C,'1. Income Statement'!$AR26,'Income Statement Source'!AI:AI)/1000 -> 13.75594 | AH26: =SUMIF('Income Statement Source'!$C:$C,'1. Income Statement'!$AR26,'Income Statement Source'!AJ:AJ)/1000 -> 15.26791 | AI26: =SUMIF('Income Statement Source'!$C:$C,'1. Income Statement'!$AR26,'Income Statement Source'!AK:AK)/1000 -> 14.83659 | AJ26: =SUMIF('Income Statement Source'!$C:$C,'1. Income Statement'!$AR26,'Income Statement Source'!AL:AL)/1000 -> 17.90564 | AK26: =SUMIF('Income Statement Source'!$C:$C,'1. Income Statement'!$AR26,'Income Statement Source'!AM:AM)/1000 -> 16.2984 | AL26: =SUMIF('Income Statement Source'!$C:$C,'1. Income Statement'!$AR26,'Income Statement Source'!AN:AN)/1000 -> 13.11337 | AM26: =SUMIF('Income Statement Source'!$C:$C,'1. Income Statement'!$AR26,'Income Statement Source'!AO:AO)/1000 -> 18.2645 | AN26: =SUMIF('Income Statement Source'!$C:$C,'1. Income Statement'!$AR26,'Income Statement Source'!AP:AP)/1000 -> 13.09253 | AO26: =SUM(AE26:AN26) -> 143.30021 | AP26: =SUM(AO26,AB26:AC26) -> 180.33079 | AR26: Pipe & Valves
B27: =+AR27 -> Wire & Cable | E27: =SUMIF('Income Statement Source'!$C:$C,'1. Income Statement'!$AR27,'Income Statement Source'!G:G)/1000 -> 3.60962 | F27: =SUMIF('Income Statement Source'!$C:$C,'1. Income Statement'!$AR27,'Income Statement Source'!H:H)/1000 -> 4.37161 | G27: =SUMIF('Income Statement Source'!$C:$C,'1. Income Statement'!$AR27,'Income Statement Source'!I:I)/1000 -> 6.68513 | H27: =SUMIF('Income Statement Source'!$C:$C,'1. Income Statement'!$AR27,'Income Statement Source'!J:J)/1000 -> 5.49789 | I27: =SUMIF('Income Statement Source'!$C:$C,'1. Income Statement'!$AR27,'Income Statement Source'!K:K)/1000 -> 5.89769 | J27: =SUMIF('Income Statement Source'!$C:$C,'1. Income Statement'!$AR27,'Income Statement Source'!L:L)/1000 -> 6.93855 | K27: =SUMIF('Income Statement Source'!$C:$C,'1. Income Statement'!$AR27,'Income Statement Source'!M:M)/1000 -> 5.78917 | L27: =SUMIF('Income Statement Source'!$C:$C,'1. Income Statement'!$AR27,'Income Statement Source'!N:N)/1000 -> 5.87802 | M27: =SUMIF('Income Statement Source'!$C:$C,'1. Income Statement'!$AR27,'Income Statement Source'!O:O)/1000 -> 7.06928 | N27: =SUMIF('Income Statement Source'!$C:$C,'1. Income Statement'!$AR27,'Income Statement Source'!P:P)/1000 -> 5.65943 | O27: =SUMIF('Income Statement Source'!$C:$C,'1. Income Statement'!$AR27,'Income Statement Source'!Q:Q)/1000 -> 4.38967 | P27: =SUMIF('Income Statement Source'!$C:$C,'1. Income Statement'!$AR27,'Income Statement Source'!R:R)/1000 -> 6.47235 | Q27: =SUM(E27:P27) -> 68.25841 | R27: =SUMIF('Income Statement Source'!$C:$C,'1. Income Statement'!$AR27,'Income Statement Source'!T:T)/1000 -> 3.90052 | S27: =SUMIF('Income Statement Source'!$C:$C,'1. Income Statement'!$AR27,'Income Statement Source'!U:U)/1000 -> 5.5374 | T27: =SUMIF('Income Statement Source'!$C:$C,'1. Income Statement'!$AR27,'Income Statement Source'!V:V)/1000 -> 7.31537 | U27: =SUMIF('Income Statement Source'!$C:$C,'1. Income Statement'!$AR27,'Income Statement Source'!W:W)/1000 -> 6.31953 | V27: =SUMIF('Income Statement Source'!$C:$C,'1. Income Statement'!$AR27,'Income Statement Source'!X:X)/1000 -> 6.87549 | W27: =SUMIF('Income Statement Source'!$C:$C,'1. Income Statement'!$AR27,'Income Statement Source'!Y:Y)/1000 -> 8.47002 | X27: =SUMIF('Income Statement Source'!$C:$C,'1. Income Statement'!$AR27,'Income Statement Source'!Z:Z)/1000 -> 7.04846 | Y27: =SUMIF('Income Statement Source'!$C:$C,'1. Income Statement'!$AR27,'Income Statement Source'!AA:AA)/1000 -> 7.08275 | Z27: =SUMIF('Income Statement Source'!$C:$C,'1. Income Statement'!$AR27,'Income Statement Source'!AB:AB)/1000 -> 8.29786 | AA27: =SUMIF('Income Statement Source'!$C:$C,'1. Income Statement'!$AR27,'Income Statement Source'!AC:AC)/1000 -> 5.70457 | AB27: =SUMIF('Income Statement Source'!$C:$C,'1. Income Statement'!$AR27,'Income Statement Source'!AD:AD)/1000 -> 5.95883 | AC27: =SUMIF('Income Statement Source'!$C:$C,'1. Income Statement'!$AR27,'Income Statement Source'!AE:AE)/1000 -> 7.20565 | AD27: =SUM(R27:AC27) -> 79.71645 | AE27: =SUMIF('Income Statement Source'!$C:$C,'1. Income Statement'!$AR27,'Income Statement Source'!AG:AG)/1000 -> 3.98623 | AF27: =SUMIF('Income Statement Source'!$C:$C,'1. Income Statement'!$AR27,'Income Statement Source'!AH:AH)/1000 -> 5.20447 | AG27: =SUMIF('Income Statement Source'!$C:$C,'1. Income Statement'!$AR27,'Income Statement Source'!AI:AI)/1000 -> 7.59876 | AH27: =SUMIF('Income Statement Source'!$C:$C,'1. Income Statement'!$AR27,'Income Statement Source'!AJ:AJ)/1000 -> 6.63018 | AI27: =SUMIF('Income Statement Source'!$C:$C,'1. Income Statement'!$AR27,'Income Statement Source'!AK:AK)/1000 -> 6.68559 | AJ27: =SUMIF('Income Statement Source'!$C:$C,'1. Income Statement'!$AR27,'Income Statement Source'!AL:AL)/1000 -> 8.75379 | AK27: =SUMIF('Income Statement Source'!$C:$C,'1. Income Statement'!$AR27,'Income Statement Source'!AM:AM)/1000 -> 7.45253 | AL27: =SUMIF('Income Statement Source'!$C:$C,'1. Income Statement'!$AR27,'Income Statement Source'!AN:AN)/1000 -> 7.23256 | AM27: =SUMIF('Income Statement Source'!$C:$C,'1. Income Statement'!$AR27,'Income Statement Source'!AO:AO)/1000 -> 9.11839 | AN27: =SUMIF('Income Statement Source'!$C:$C,'1. Income Statement'!$AR27,'Income Statement Source'!AP:AP)/1000 -> 6.35552 | AO27: =SUM(AE27:AN27) -> 69.01802 | AP27: =SUM(AO27,AB27:AC27) -> 82.1825 | AR27: Wire & Cable
B28: =+AR28 -> Equipment Rental | E28: =SUMIF('Income Statement Source'!$C:$C,'1. Income Statement'!$AR28,'Income Statement Source'!G:G)/1000 -> 2.51848 | F28: =SUMIF('Income Statement Source'!$C:$C,'1. Income Statement'!$AR28,'Income Statement Source'!H:H)/1000 -> 3.58479 | G28: =SUMIF('Income Statement Source'!$C:$C,'1. Income Statement'!$AR28,'Income Statement Source'!I:I)/1000 -> 4.55144 | H28: =SUMIF('Income Statement Source'!$C:$C,'1. Income Statement'!$AR28,'Income Statement Source'!J:J)/1000 -> 3.66865 | I28: =SUMIF('Income Statement Source'!$C:$C,'1. Income Statement'!$AR28,'Income Statement Source'!K:K)/1000 -> 4.02613 | J28: =SUMIF('Income Statement Source'!$C:$C,'1. Income Statement'!$AR28,'Income Statement Source'!L:L)/1000 -> 5.81517 | K28: =SUMIF('Income Statement Source'!$C:$C,'1. Income Statement'!$AR28,'Income Statement Source'!M:M)/1000 -> 4.33839 | L28: =SUMIF('Income Statement Source'!$C:$C,'1. Income Statement'!$AR28,'Income Statement Source'!N:N)/1000 -> 4.1258 | M28: =SUMIF('Income Statement Source'!$C:$C,'1. Income Statement'!$AR28,'Income Statement Source'!O:O)/1000 -> 4.86586 | N28: =SUMIF('Income Statement Source'!$C:$C,'1. Income Statement'!$AR28,'Income Statement Source'!P:P)/1000 -> 3.6313 | O28: =SUMIF('Income Statement Source'!$C:$C,'1. Income Statement'!$AR28,'Income Statement Source'!Q:Q)/1000 -> 3.57506 | P28: =SUMIF('Income Statement Source'!$C:$C,'1. Income Statement'!$AR28,'Income Statement Source'!R:R)/1000 -> 4.78671 | Q28: =SUM(E28:P28) -> 49.48778 | R28: =SUMIF('Income Statement Source'!$C:$C,'1. Income Statement'!$AR28,'Income Statement Source'!T:T)/1000 -> 3.68157 | S28: =SUMIF('Income Statement Source'!$C:$C,'1. Income Statement'!$AR28,'Income Statement Source'!U:U)/1000 -> 4.70851 | T28: =SUMIF('Income Statement Source'!$C:$C,'1. Income Statement'!$AR28,'Income Statement Source'!V:V)/1000 -> 7.02594 | U28: =SUMIF('Income Statement Source'!$C:$C,'1. Income Statement'!$AR28,'Income Statement Source'!W:W)/1000 -> 5.91875 | V28: =SUMIF('Income Statement Source'!$C:$C,'1. Income Statement'!$AR28,'Income Statement Source'!X:X)/1000 -> 7.04082 | W28: =SUMIF('Income Statement Source'!$C:$C,'1. Income Statement'!$AR28,'Income Statement Source'!Y:Y)/1000 -> 8.51923 | X28: =SUMIF('Income Statement Source'!$C:$C,'1. Income Statement'!$AR28,'Income Statement Source'!Z:Z)/1000 -> 7.54677 | Y28: =SUMIF('Income Statement Source'!$C:$C,'1. Income Statement'!$AR28,'Income Statement Source'!AA:AA)/1000 -> 7.58808 | Z28: =SUMIF('Income Statement Source'!$C:$C,'1. Income Statement'!$AR28,'Income Statement Source'!AB:AB)/1000 -> 8.75482 | AA28: =SUMIF('Income Statement Source'!$C:$C,'1. Income Statement'!$AR28,'Income Statement Source'!AC:AC)/1000 -> 5.44283 | AB28: =SUMIF('Income Statement Source'!$C:$C,'1. Income Statement'!$AR28,'Income Statement Source'!AD:AD)/1000 -> 5.27398 | AC28: =SUMIF('Income Statement Source'!$C:$C,'1. Income Statement'!$AR28,'Income Statement Source'!AE:AE)/1000 -> 7.39418 | AD28: =SUM(R28:AC28) -> 78.89548 | AE28: =SUMIF('Income Statement Source'!$C:$C,'1. Income Statement'!$AR28,'Income Statement Source'!AG:AG)/1000 -> 3.34906 | AF28: =SUMIF('Income Statement Source'!$C:$C,'1. Income Statement'!$AR28,'Income Statement Source'!AH:AH)/1000 -> 4.58164 | AG28: =SUMIF('Income Statement Source'!$C:$C,'1. Income Statement'!$AR28,'Income Statement Source'!AI:AI)/1000 -> 5.92902 | AH28: =SUMIF('Income Statement Source'!$C:$C,'1. Income Statement'!$AR28,'Income Statement Source'!AJ:AJ)/1000 -> 4.93635 | AI28: =SUMIF('Income Statement Source'!$C:$C,'1. Income Statement'!$AR28,'Income Statement Source'!AK:AK)/1000 -> 5.56752 | AJ28: =SUMIF('Income Statement Source'!$C:$C,'1. Income Statement'!$AR28,'Income Statement Source'!AL:AL)/1000 -> 7.05902 | AK28: =SUMIF('Income Statement Source'!$C:$C,'1. Income Statement'!$AR28,'Income Statement Source'!AM:AM)/1000 -> 5.65396 | AL28: =SUMIF('Income Statement Source'!$C:$C,'1. Income Statement'!$AR28,'Income Statement Source'!AN:AN)/1000 -> 5.95739 | AM28: =SUMIF('Income Statement Source'!$C:$C,'1. Income Statement'!$AR28,'Income Statement Source'!AO:AO)/1000 -> 5.79226 | AN28: =SUMIF('Income Statement Source'!$C:$C,'1. Income Statement'!$AR28,'Income Statement Source'!AP:AP)/1000 -> 5.53821 | AO28: =SUM(AE28:AN28) -> 54.36443 | AP28: =SUM(AO28,AB28:AC28) -> 67.03259 | AR28: Equipment Rental
B29: =+AR29 -> Job Supplies & Consumables | E29: =SUMIF('Income Statement Source'!$C:$C,'1. Income Statement'!$AR29,'Income Statement Source'!G:G)/1000 -> 1.57881 | F29: =SUMIF('Income Statement Source'!$C:$C,'1. Income Statement'!$AR29,'Income Statement Source'!H:H)/1000 -> 1.75111 | G29: =SUMIF('Income Statement Source'!$C:$C,'1. Income Statement'!$AR29,'Income Statement Source'!I:I)/1000 -> 2.39149 | H29: =SUMIF('Income Statement Source'!$C:$C,'1. Income Statement'!$AR29,'Income Statement Source'!J:J)/1000 -> 2.07259 | I29: =SUMIF('Income Statement Source'!$C:$C,'1. Income Statement'!$AR29,'Income Statement Source'!K:K)/1000 -> 2.12019 | J29: =SUMIF('Income Statement Source'!$C:$C,'1. Income Statement'!$AR29,'Income Statement Source'!L:L)/1000 -> 2.9964 | K29: =SUMIF('Income Statement Source'!$C:$C,'1. Income Statement'!$AR29,'Income Statement Source'!M:M)/1000 -> 2.24103 | L29: =SUMIF('Income Statement Source'!$C:$C,'1. Income Statement'!$AR29,'Income Statement Source'!N:N)/1000 -> 2.03537 | M29: =SUMIF('Income Statement Source'!$C:$C,'1. Income Statement'!$AR29,'Income Statement Source'!O:O)/1000 -> 2.94044 | N29: =SUMIF('Income Statement Source'!$C:$C,'1. Income Statement'!$AR29,'Income Statement Source'!P:P)/1000 -> 2.08361 | O29: =SUMIF('Income Statement Source'!$C:$C,'1. Income Statement'!$AR29,'Income Statement Source'!Q:Q)/1000 -> 1.78521 | P29: =SUMIF('Income Statement Source'!$C:$C,'1. Income Statement'!$AR29,'Income Statement Source'!R:R)/1000 -> 2.88374 | Q29: =SUM(E29:P29) -> 26.87999 | R29: =SUMIF('Income Statement Source'!$C:$C,'1. Income Statement'!$AR29,'Income Statement Source'!T:T)/1000 -> 1.55321 | S29: =SUMIF('Income Statement Source'!$C:$C,'1. Income Statement'!$AR29,'Income Statement Source'!U:U)/1000 -> 1.96974 | T29: =SUMIF('Income Statement Source'!$C:$C,'1. Income Statement'!$AR29,'Income Statement Source'!V:V)/1000 -> 3.02294 | U29: =SUMIF('Income Statement Source'!$C:$C,'1. Income Statement'!$AR29,'Income Statement Source'!W:W)/1000 -> 2.52509 | V29: =SUMIF('Income Statement Source'!$C:$C,'1. Income Statement'!$AR29,'Income Statement Source'!X:X)/1000 -> 2.7116 | W29: =SUMIF('Income Statement Source'!$C:$C,'1. Income Statement'!$AR29,'Income Statement Source'!Y:Y)/1000 -> 3.5038 | X29: =SUMIF('Income Statement Source'!$C:$C,'1. Income Statement'!$AR29,'Income Statement Source'!Z:Z)/1000 -> 3.19273 | Y29: =SUMIF('Income Statement Source'!$C:$C,'1. Income Statement'!$AR29,'Income Statement Source'!AA:AA)/1000 -> 3.00584 | Z29: =SUMIF('Income Statement Source'!$C:$C,'1. Income Statement'!$AR29,'Income Statement Source'!AB:AB)/1000 -> 2.92531 | AA29: =SUMIF('Income Statement Source'!$C:$C,'1. Income Statement'!$AR29,'Income Statement Source'!AC:AC)/1000 -> 2.50119 | AB29: =SUMIF('Income Statement Source'!$C:$C,'1. Income Statement'!$AR29,'Income Statement Source'!AD:AD)/1000 -> 2.46293 | AC29: =SUMIF('Income Statement Source'!$C:$C,'1. Income Statement'!$AR29,'Income Statement Source'!AE:AE)/1000 -> 3.17195 | AD29: =SUM(R29:AC29) -> 32.54633 | AE29: =SUMIF('Income Statement Source'!$C:$C,'1. Income Statement'!$AR29,'Income Statement Source'!AG:AG)/1000 -> 1.65568 | AF29: =SUMIF('Income Statement Source'!$C:$C,'1. Income Statement'!$AR29,'Income Statement Source'!AH:AH)/1000 -> 2.43077 | AG29: =SUMIF('Income Statement Source'!$C:$C,'1. Income Statement'!$AR29,'Income Statement Source'!AI:AI)/1000 -> 3.3537 | AH29: =SUMIF('Income Statement Source'!$C:$C,'1. Income Statement'!$AR29,'Income Statement Source'!AJ:AJ)/1000 -> 3.0686 | AI29: =SUMIF('Income Statement Source'!$C:$C,'1. Income Statement'!$AR29,'Income Statement Source'!AK:AK)/1000 -> 2.59056 | AJ29: =SUMIF('Income Statement Source'!$C:$C,'1. Income Statement'!$AR29,'Income Statement Source'!AL:AL)/1000 -> 3.63916 | AK29: =SUMIF('Income Statement Source'!$C:$C,'1. Income Statement'!$AR29,'Income Statement Source'!AM:AM)/1000 -> 3.08563 | AL29: =SUMIF('Income Statement Source'!$C:$C,'1. Income Statement'!$AR29,'Income Statement Source'!AN:AN)/1000 -> 2.85981 | AM29: =SUMIF('Income Statement Source'!$C:$C,'1. Income Statement'!$AR29,'Income Statement Source'!AO:AO)/1000 -> 3.80183 | AN29: =SUMIF('Income Statement Source'!$C:$C,'1. Income Statement'!$AR29,'Income Statement Source'!AP:AP)/1000 -> 2.88548 | AO29: =SUM(AE29:AN29) -> 29.37122 | AP29: =SUM(AO29,AB29:AC29) -> 35.0061 | AR29: Job Supplies & Consumables
B30: =+B23 -> Materials & Equipment | E30: =SUM(E24:E29) -> 49.0146 | F30: =SUM(F24:F29) -> 60.37854 | G30: =SUM(G24:G29) -> 82.90482 | H30: =SUM(H24:H29) -> 67.48466 | I30: =SUM(I24:I29) -> 71.13853 | J30: =SUM(J24:J29) -> 94.72672 | K30: =SUM(K24:K29) -> 81.72669 | L30: =SUM(L24:L29) -> 70.35796 | ... AP30: =SUM(AP24:AP29) -> 1152.701
E31: =IFERROR(E30/E$19,0) -> 0.25800414 | F31: =IFERROR(F30/F$19,0) -> 0.26565738 | G31: =IFERROR(G30/G$19,0) -> 0.26950791 | H31: =IFERROR(H30/H$19,0) -> 0.26091734 | I31: =IFERROR(I30/I$19,0) -> 0.2617533 | J31: =IFERROR(J30/J$19,0) -> 0.25723126 | K31: =IFERROR(K30/K$19,0) -> 0.27017392 | L31: =IFERROR(L30/L$19,0) -> 0.25379591 | ... AP31: =IFERROR(AP30/AP$19,0) -> 0.27178201
B32: Subcontract
B33: =+AR33 -> Sprinkler Subcontractor Labor | E33: =SUMIF('Income Statement Source'!$C:$C,'1. Income Statement'!$AR33,'Income Statement Source'!G:G)/1000 -> 68.64558 | F33: =SUMIF('Income Statement Source'!$C:$C,'1. Income Statement'!$AR33,'Income Statement Source'!H:H)/1000 -> 87.77917 | G33: =SUMIF('Income Statement Source'!$C:$C,'1. Income Statement'!$AR33,'Income Statement Source'!I:I)/1000 -> 9.70356 | H33: =SUMIF('Income Statement Source'!$C:$C,'1. Income Statement'!$AR33,'Income Statement Source'!J:J)/1000 -> 53.70016 | I33: =SUMIF('Income Statement Source'!$C:$C,'1. Income Statement'!$AR33,'Income Statement Source'!K:K)/1000 -> 60.77124 | J33: =SUMIF('Income Statement Source'!$C:$C,'1. Income Statement'!$AR33,'Income Statement Source'!L:L)/1000 -> 148.81247 | K33: =SUMIF('Income Statement Source'!$C:$C,'1. Income Statement'!$AR33,'Income Statement Source'!M:M)/1000 -> 9.92969 | L33: =SUMIF('Income Statement Source'!$C:$C,'1. Income Statement'!$AR33,'Income Statement Source'!N:N)/1000 -> 61.47874 | M33: =SUMIF('Income Statement Source'!$C:$C,'1. Income Statement'!$AR33,'Income Statement Source'!O:O)/1000 -> 153.63807 | N33: =SUMIF('Income Statement Source'!$C:$C,'1. Income Statement'!$AR33,'Income Statement Source'!P:P)/1000 -> 8.65425 | O33: =SUMIF('Income Statement Source'!$C:$C,'1. Income Statement'!$AR33,'Income Statement Source'!Q:Q)/1000 -> 51.5449 | P33: =SUMIF('Income Statement Source'!$C:$C,'1. Income Statement'!$AR33,'Income Statement Source'!R:R)/1000 -> 70.20015 | Q33: =SUM(E33:P33) -> 784.85798 | R33: =SUMIF('Income Statement Source'!$C:$C,'1. Income Statement'!$AR33,'Income Statement Source'!T:T)/1000 -> 63.8535 | S33: =SUMIF('Income Statement Source'!$C:$C,'1. Income Statement'!$AR33,'Income Statement Source'!U:U)/1000 -> 79.89286 | T33: =SUMIF('Income Statement Source'!$C:$C,'1. Income Statement'!$AR33,'Income Statement Source'!V:V)/1000 -> 191.93299 | U33: =SUMIF('Income Statement Source'!$C:$C,'1. Income Statement'!$AR33,'Income Statement Source'!W:W)/1000 -> 14.94238 | V33: =SUMIF('Income Statement Source'!$C:$C,'1. Income Statement'!$AR33,'Income Statement Source'!X:X)/1000 -> 102.26975 | W33: =SUMIF('Income Statement Source'!$C:$C,'1. Income Statement'!$AR33,'Income Statement Source'!Y:Y)/1000 -> 130.93173 | X33: =SUMIF('Income Statement Source'!$C:$C,'1. Income Statement'!$AR33,'Income Statement Source'!Z:Z)/1000 -> 207.77417 | Y33: =SUMIF('Income Statement Source'!$C:$C,'1. Income Statement'!$AR33,'Income Statement Source'!AA:AA)/1000 -> 17.11902 | Z33: =SUMIF('Income Statement Source'!$C:$C,'1. Income Statement'!$AR33,'Income Statement Source'!AB:AB)/1000 -> 118.43041 | AA33: =SUMIF('Income Statement Source'!$C:$C,'1. Income Statement'!$AR33,'Income Statement Source'!AC:AC)/1000 -> 87.04569 | AB33: =SUMIF('Income Statement Source'!$C:$C,'1. Income Statement'!$AR33,'Income Statement Source'!AD:AD)/1000 -> 159.36507 | AC33: =SUMIF('Income Statement Source'!$C:$C,'1. Income Statement'!$AR33,'Income Statement Source'!AE:AE)/1000 -> 17.59675 | AD33: =SUM(R33:AC33) -> 1191.1543 | AE33: =SUMIF('Income Statement Source'!$C:$C,'1. Income Statement'!$AR33,'Income Statement Source'!AG:AG)/1000 -> 49.12704 | AF33: =SUMIF('Income Statement Source'!$C:$C,'1. Income Statement'!$AR33,'Income Statement Source'!AH:AH)/1000 -> 65.7948 | AG33: =SUMIF('Income Statement Source'!$C:$C,'1. Income Statement'!$AR33,'Income Statement Source'!AI:AI)/1000 -> 89.6791 | AH33: =SUMIF('Income Statement Source'!$C:$C,'1. Income Statement'!$AR33,'Income Statement Source'!AJ:AJ)/1000 -> 150.91857 | AI33: =SUMIF('Income Statement Source'!$C:$C,'1. Income Statement'!$AR33,'Income Statement Source'!AK:AK)/1000 -> 11.57816 | AJ33: =SUMIF('Income Statement Source'!$C:$C,'1. Income Statement'!$AR33,'Income Statement Source'!AL:AL)/1000 -> 101.82188 | AK33: =SUMIF('Income Statement Source'!$C:$C,'1. Income Statement'!$AR33,'Income Statement Source'!AM:AM)/1000 -> 80.43095 | AL33: =SUMIF('Income Statement Source'!$C:$C,'1. Income Statement'!$AR33,'Income Statement Source'!AN:AN)/1000 -> 145.96461 | AM33: =SUMIF('Income Statement Source'!$C:$C,'1. Income Statement'!$AR33,'Income Statement Source'!AO:AO)/1000 -> 14.04965 | AN33: =SUMIF('Income Statement Source'!$C:$C,'1. Income Statement'!$AR33,'Income Statement Source'!AP:AP)/1000 -> 73.11584 | AO33: =SUM(AE33:AN33) -> 782.4806 | AP33: =SUM(AO33,AB33:AC33) -> 959.44242 | AR33: Sprinkler Subcontractor Labor
